<mujoco model="gofa_arm">
    <compiler angle="radian" meshdir="assets" autolimits="true"/>
    <!--<size njmax="500" nconmax="100" />-->
    <asset>
        <mesh name="base_link" file="../robot/models/gofa_model/assets/base_link.STL"/>
        <mesh name="link_1" file="../robot/models/gofa_model/assets/link_1.STL" />
        <mesh name="link_2" file="../robot/models/gofa_model/assets/link_2.STL" />
        <mesh name="link_3" file="../robot/models/gofa_model/assets/link_3.STL" />
        <mesh name="link_4" file="../robot/models/gofa_model/assets/link_4.STL" />
        <mesh name="link_5" file="../robot/models/gofa_model/assets/link_5.STL" />
        <mesh name="link_6" file="../robot/models/gofa_model/assets/link_6.STL" />
    </asset>
    <worldbody>
        <geom type="mesh" rgba="0.6 0.6 0.6 1" mesh="base_link" />
        <body name="link_1" pos="0 0 0.1679">
            <inertial pos="0 -0.02161 0.09328" quat="0.674445 0.738316 0.00271381 -0.00245913" mass="4.93" diaginertia="0.0172761 0.0158887 0.00965726" />
            <joint name="joint_1" pos="0 0 0" axis="0 0 1" limited="true" range="-3.14159 3.14159" damping="50000" stiffness="500000" />
            <geom type="mesh" rgba="0.6 0.6 0.6 1" mesh="link_1" />
            <body name="link_2" pos="0 -0.0609 0.0971">
                <inertial pos="0 -0.06794 0.2203" quat="0.707114 -0.00010546 -5.60132e-05 0.707099" mass="3.36" diaginertia="0.10729 0.1041 0.00718999" />
                <joint name="joint_2" pos="0 0 0" axis="0 1 0" limited="true" range="-3.14159 3.14159" damping="50000" stiffness="500000" />
                <geom type="mesh" rgba="0.6 0.6 0.6 1" mesh="link_2" />
                <body name="link_3" pos="0 0 0.444">
                    <inertial pos="0.00581 0.04011 0.00507" quat="0.97157 0.180027 -0.100011 0.116787" mass="5.18" diaginertia="0.0316407 0.0251237 0.0154205" />
                    <joint name="joint_3" pos="0 0 0" axis="0 1 0" limited="true" range="-3.92699 1.48353" damping="50000" stiffness="500000" />
                    <geom type="mesh" rgba="0.6 0.6 0.6 1" mesh="link_3" />
                    <body name="link_4" pos="0.113 0.0609 0.11">
                        <inertial pos="0.09499 0.02668 -0.00157" quat="0.195396 0.716032 -0.00835779 0.670111" mass="3.79" diaginertia="0.0564317 0.0559657 0.00734569" />
                        <joint name="joint_4" pos="0 0 0" axis="1 0 0" limited="true" range="-3.14159 3.14159" damping="50000" stiffness="500000"/>
                        <geom type="mesh" rgba="0.6 0.6 0.6 1" mesh="link_4" />
                        <body name="link_5" pos="0.357 0.0565 0">
                            <inertial pos="-0.0084 -0.04567 0.0329" quat="0.821583 -0.00122227 0.292485 0.489338" mass="4.26" diaginertia="0.0187008 0.0163414 0.0137768" />
                            <joint name="joint_5" pos="0 0 0" axis="0 1 0" limited="true" range="-3.14159 3.14159" damping="50000" stiffness="500000" />
                            <geom type="mesh" rgba="0.6 0.6 0.6 1" mesh="link_5" />
                            <body name="link_6" pos="0.101 -0.0565 0.08">
                                <inertial pos="-0.05129 -2e-05 4e-05" quat="0.408245 0.912857 -0.00452271 0.00269951" mass="1.04" diaginertia="0.00124393 0.00101085 0.00101003" />
                                <joint name="joint_6" pos="0 0 0" axis="1 0 0" limited="true" range="-4.71239 4.71239" damping="50000" stiffness="500000" />
                                <geom type="mesh" rgba="0.6 0.6 0.6 1" mesh="link_6" />
                            </body>
                        </body>
                    </body>
                </body>
            </body>
        </body>
    </worldbody>
</mujoco>